<?xml version="1.0"?>

<robot xmlns:xacro="http://www.ros.org/wiki/xacro" 
    xmlns:sensor="http://playerstage.sourceforge.net/gazebo/xmlschema/#sensor"
    xmlns:controller="http://playerstage.sourceforge.net/gazebo/xmlschema/#controller"
    xmlns:interface="http://playerstage.sourceforge.net/gazebo/xmlschema/#interface"
    name="swing_robot">

  <link name="base_link">

    <visual>
      <origin rpy="1.570796 0 0" xyz="0 0 0"/>
      <geometry>
         <mesh filename="package://swing_robot/meshes/frames.stl"/>
      </geometry>
      <material name="yellow">
        <color rgba="1 1 0 1"/>
      </material>
    </visual>
    <collision>
      <origin rpy="1.570796 0 0" xyz="0 0 0"/>
      <geometry>
         <mesh filename="package://swing_robot/meshes/frames.stl"/>
      </geometry>
    </collision>
    <inertial>
        <origin xyz="0.0 0.0 0.0" rpy="0.0 0.0 0.0"/>
        <mass value="3.314"/>
        <inertia ixx="463814.860" ixy="323.087" ixz="0.0" iyy="223494.895" iyz="0.0" izz="457336.445"/>
    </inertial>
  </link>

  <joint name="swing joint" type="revolute">
    <parent link="base_link"/>
    <child link="swing_link"/>
    <origin xyz="0 0 0.599704"/>
    <axis xyz="1 0 0" />
    <limit effort="300" velocity="0.1" lower="-3.14" upper="3.14"/>
    <dynamics damping="50" friction="1"/>
  </joint>

  <link name="swing_link">
    <visual>
      <geometry>
         <mesh filename="package://swing_robot/meshes/swing.stl"/>
      </geometry>
      <origin rpy="1.570796 0 0" xyz="0 0 0"/>
      <material name="red">
        <color rgba="0 0 1 1"/>
      </material>
    </visual>
    <collision>
      <geometry>
         <mesh filename="package://swing_robot/meshes/swing.stl"/>
      </geometry>
      <origin rpy="1.570796 0 0" xyz="0 0 0"/>
    </collision>
    <inertial>
        <origin xyz="0.0 0.0 0" rpy="1.570796 0 0"/>
        <mass value="4.443"/>
        <inertia ixx="22383.593" ixy="5442.330" ixz="-438.500" iyy="3976.186" iyz="764.536" izz="26027.494"/>
    </inertial>
  </link>
</robot>